Workbook

Sheet Overview
A1: NCOMA / WIYO! - Copy Review
A2: Generated May 26, 2026 | 13:26 | Reviewers: Pablo | Matt | Conrad | _ | Counts auto-update as you change Approval values
A4: How the two-step review works
A5: 1. Open the tab for the page you're reviewing (tabs at bottom).
A6: 2. Each row = one section. Screenshot on the left, copy in the middle, edit columns on the right.
A7: 3. PROPOSE: paste your edit in 'Suggested edit', pick 'Edit type' + your name in 'Proposed by'.
A8: 4. APPROVE: another reviewer sets 'Approval' and picks their name in 'Approved by'.
A9: 5. APPLIED: once the edit is live, set Approval to 'Applied'.
A10: 6. The dashboard below updates automatically from each page tab.
A13: Approval colors
A14: Awaiting review | B14: Edit proposed but not yet reviewed
A15: Approved | B15: Edit accepted — will be applied
A16: Rejected | B16: Edit declined — current copy stays
A17: Needs discussion | B17: Team conversation needed
A18: Applied | B18: Edit has been applied to the live site
A21: Live page dashboard | B21: (counts update automatically)
A22: Page | B22: Sections | C22: Awaiting | D22: Approved | E22: Rejected | F22: Needs disc. | G22: Applied | H22: Progress | I22: Status | J22: Live link
A23: Homepage | B23: =COUNTA('Homepage'!G6:G200) | C23: =COUNTIF('Homepage'!G6:G200,"Awaiting review") | D23: =COUNTIF('Homepage'!G6:G200,"Approved") | E23: =COUNTIF('Homepage'!G6:G200,"Rejected") | F23: =COUNTIF('Homepage'!G6:G200,"Needs discussion") | G23: =COUNTIF('Homepage'!G6:G200,"Applied") | H23: =IFERROR((D23+G23)/B23,0) | I23: =IF(B23=0,"--",IF((D23+G23)=B23,"Complete",IF((D23+G23)=0,"To review","In progress"))) | J23: Open
A24: The WIYO! Seal | B24: =COUNTA('The WIYO! Seal'!G6:G200) | C24: =COUNTIF('The WIYO! Seal'!G6:G200,"Awaiting review") | D24: =COUNTIF('The WIYO! Seal'!G6:G200,"Approved") | E24: =COUNTIF('The WIYO! Seal'!G6:G200,"Rejected") | F24: =COUNTIF('The WIYO! Seal'!G6:G200,"Needs discussion") | G24: =COUNTIF('The WIYO! Seal'!G6:G200,"Applied") | H24: =IFERROR((D24+G24)/B24,0) | I24: =IF(B24=0,"--",IF((D24+G24)=B24,"Complete",IF((D24+G24)=0,"To review","In progress"))) | J24: Open
A25: For Operators | B25: =COUNTA('For Operators'!G6:G200) | C25: =COUNTIF('For Operators'!G6:G200,"Awaiting review") | D25: =COUNTIF('For Operators'!G6:G200,"Approved") | E25: =COUNTIF('For Operators'!G6:G200,"Rejected") | F25: =COUNTIF('For Operators'!G6:G200,"Needs discussion") | G25: =COUNTIF('For Operators'!G6:G200,"Applied") | H25: =IFERROR((D25+G25)/B25,0) | I25: =IF(B25=0,"--",IF((D25+G25)=B25,"Complete",IF((D25+G25)=0,"To review","In progress"))) | J25: Open
A26: For Consumers | B26: =COUNTA('For Consumers'!G6:G200) | C26: =COUNTIF('For Consumers'!G6:G200,"Awaiting review") | D26: =COUNTIF('For Consumers'!G6:G200,"Approved") | E26: =COUNTIF('For Consumers'!G6:G200,"Rejected") | F26: =COUNTIF('For Consumers'!G6:G200,"Needs discussion") | G26: =COUNTIF('For Consumers'!G6:G200,"Applied") | H26: =IFERROR((D26+G26)/B26,0) | I26: =IF(B26=0,"--",IF((D26+G26)=B26,"Complete",IF((D26+G26)=0,"To review","In progress"))) | J26: Open
A27: About NCOMA | B27: =COUNTA('About NCOMA'!G6:G200) | C27: =COUNTIF('About NCOMA'!G6:G200,"Awaiting review") | D27: =COUNTIF('About NCOMA'!G6:G200,"Approved") | E27: =COUNTIF('About NCOMA'!G6:G200,"Rejected") | F27: =COUNTIF('About NCOMA'!G6:G200,"Needs discussion") | G27: =COUNTIF('About NCOMA'!G6:G200,"Applied") | H27: =IFERROR((D27+G27)/B27,0) | I27: =IF(B27=0,"--",IF((D27+G27)=B27,"Complete",IF((D27+G27)=0,"To review","In progress"))) | J27: Open
A28: Contact | B28: =COUNTA('Contact'!G6:G200) | C28: =COUNTIF('Contact'!G6:G200,"Awaiting review") | D28: =COUNTIF('Contact'!G6:G200,"Approved") | E28: =COUNTIF('Contact'!G6:G200,"Rejected") | F28: =COUNTIF('Contact'!G6:G200,"Needs discussion") | G28: =COUNTIF('Contact'!G6:G200,"Applied") | H28: =IFERROR((D28+G28)/B28,0) | I28: =IF(B28=0,"--",IF((D28+G28)=B28,"Complete",IF((D28+G28)=0,"To review","In progress"))) | J28: Open
A29: Find Certified | B29: =COUNTA('Find Certified'!G6:G200) | C29: =COUNTIF('Find Certified'!G6:G200,"Awaiting review") | D29: =COUNTIF('Find Certified'!G6:G200,"Approved") | E29: =COUNTIF('Find Certified'!G6:G200,"Rejected") | F29: =COUNTIF('Find Certified'!G6:G200,"Needs discussion") | G29: =COUNTIF('Find Certified'!G6:G200,"Applied") | H29: =IFERROR((D29+G29)/B29,0) | I29: =IF(B29=0,"--",IF((D29+G29)=B29,"Complete",IF((D29+G29)=0,"To review","In progress"))) | J29: Open
A30: Field Notes Index | B30: =COUNTA('Field Notes Index'!G6:G200) | C30: =COUNTIF('Field Notes Index'!G6:G200,"Awaiting review") | D30: =COUNTIF('Field Notes Index'!G6:G200,"Approved") | E30: =COUNTIF('Field Notes Index'!G6:G200,"Rejected") | F30: =COUNTIF('Field Notes Index'!G6:G200,"Needs discussion") | G30: =COUNTIF('Field Notes Index'!G6:G200,"Applied") | H30: =IFERROR((D30+G30)/B30,0) | I30: =IF(B30=0,"--",IF((D30+G30)=B30,"Complete",IF((D30+G30)=0,"To review","In progress"))) | J30: Open
A31: Reports Index | B31: =COUNTA('Reports Index'!G6:G200) | C31: =COUNTIF('Reports Index'!G6:G200,"Awaiting review") | D31: =COUNTIF('Reports Index'!G6:G200,"Approved") | E31: =COUNTIF('Reports Index'!G6:G200,"Rejected") | F31: =COUNTIF('Reports Index'!G6:G200,"Needs discussion") | G31: =COUNTIF('Reports Index'!G6:G200,"Applied") | H31: =IFERROR((D31+G31)/B31,0) | I31: =IF(B31=0,"--",IF((D31+G31)=B31,"Complete",IF((D31+G31)=0,"To review","In progress"))) | J31: Open
A32: Cost Calculator | B32: =COUNTA('Cost Calculator'!G6:G200) | C32: =COUNTIF('Cost Calculator'!G6:G200,"Awaiting review") | D32: =COUNTIF('Cost Calculator'!G6:G200,"Approved") | E32: =COUNTIF('Cost Calculator'!G6:G200,"Rejected") | F32: =COUNTIF('Cost Calculator'!G6:G200,"Needs discussion") | G32: =COUNTIF('Cost Calculator'!G6:G200,"Applied") | H32: =IFERROR((D32+G32)/B32,0) | I32: =IF(B32=0,"--",IF((D32+G32)=B32,"Complete",IF((D32+G32)=0,"To review","In progress"))) | J32: Open
A33: TOTALS | B33: =SUM(B23:B32) | C33: =SUM(C23:C32) | D33: =SUM(D23:D32) | E33: =SUM(E23:E32) | F33: =SUM(F23:F32) | G33: =SUM(G23:G32) | H33: =IFERROR((D33+G33)/B33,0) | I33: =IF((D33+G33)=B33,"ALL DONE",IF((D33+G33)=0,"NOT STARTED","IN PROGRESS"))

Sheet Homepage
A1: Homepage
A2: / | https://www.whatisinyouroil.com/ | 2026-05-26 13:25 | 15 sections
A3: Open live page
A5: Section preview | B5: Section | C5: Current copy | D5: Suggested edit | E5: Edit type | F5: Proposed by | G5: Approval | H5: Approved by | I5: Notes
B6: SEO - Title & meta | C6: [Page <title>] NCOMA — National Cooking Oil Management Association [Meta description] The first industry-built certification for cooking oil management in American commercial kitchens. Know your oil. | G6: Awaiting review
B7: Navigation | C7: [Link/CTA] NCOMA [Link/CTA] The Seal [Link/CTA] For Operators [Link/CTA] For Consumers [Link/CTA] Oil Atlas [Link/CTA] Field Notes [Link/CTA] Reports [Link/CTA] About [Link/CTA] Get Certified | G7: Awaiting review
B8: What is in your oil? | C8: [H1] What is in your oil ? [Paragraph] Carcinogens. Aldehydes. Trans fats. Free radicals. If your restaurant isn't testing its frying oil, this is what's in it — and what your customers are eating. 78% of American restaurants have never checked. [Link/CTA] See What's In the Oil [Link/CTA] Fix It — Get Certified | G8: Awaiting review
B9: This is what's actually in degraded frying oil. | C9: [Paragraph] The Problem [H2] This is what's actually in degraded frying oil. [Paragraph] When frying oil breaks down — through heat, oxygen, water, and time — it doesn't just get “old.” It becomes a cocktail of toxic compounds that transfer directly into the food your customers eat. [Paragraph] 20× [Paragraph] Above WHO Limits [Paragraph] PUFA-rich oils at frying temperature produce aldehyde concentrations approximately 20 times higher than WHO recommended limits. These compounds absorb directly into the food. [Paragraph] Grootveld et al. (2021), Frontiers in Nutrition [Paragraph] 78% [Paragraph] Have Never Tested [Paragraph] Of 412 US operators surveyed, 78% have never measured the Total Polar Materials in their frying oil. Not once. They don't know what's in it. Neither do their customers. [Paragraph] NCOMA 2026 State of the Fryer Survey [Paragraph] Federal Standards [Paragraph] Germany, France, Spain, Belgium, China, India — 20+ countries mandate TPM discard thresholds. The United States has no federal limit, no required testing, no standard of any kind. [Paragraph] FDA / USDA regulatory review; Codex Alimentarius | G9: Awaiting review
B10: Every hour your oil degrades, it produces these. | C10: [Paragraph] The Chemistry of Neglect [H2] Every hour your oil degrades, it produces these. [H3] 4-Hydroxynonenal (4-HNE) [Paragraph] A lipid peroxidation product from omega-6 PUFA oxidation. Classified as cytotoxic and genotoxic. Linked to oxidative stress, inflammation, and cell damage in peer-reviewed literature. Generated in every fryer running degraded PUFA-rich oil. [H3] Acrolein [Paragraph] The simplest unsaturated aldehyde. A respiratory and gastrointestinal irritant. Produced when glycerol in oil breaks down at frying temperatures. The compound responsible for the acrid smell near an overused fryer. [H3] Trans,trans-2,4-decadienal [Paragraph] The dominant aldehyde from linoleic acid oxidation. What you taste as “rancid” or “fishy” in degraded oil. Absorbed into the food during frying. Diners eat it. Staff breathe it. [H3] Total Polar Materials (TPM) [Paragraph] The umbrella measurement for all degradation products — polymers, dimers, free fatty acids, oxidized triglycerides. Fresh oil: 2–4% TPM. Legal limit in Europe: 24–27% TPM. Many US fryers: nobody has ever checked. [Paragraph] 30%+ [Paragraph] TPM levels found in unregulated US fryers [Paragraph] No US survey exists. Delhi street vendors: 65%+ exceeded threshold. Athens restaurants: 17%. The US — with no testing — is flying blind. [Paragraph] 3 days [Paragraph] Median oil change frequency — regardless of oil type, volume, or filtration [Paragraph] A fixed schedule that gets every operation wrong. Wastes good oil. Serves food in bad oil. Condition-based testing is the only answer. [Paragraph] 20–40% [Paragraph] More fat absorbed by food fried in degraded oil [Paragraph] Saguy & Dana (2003), Journal of Food Engineering | G10: Awaiting review
B11: This is what degraded oil does to the people eating it. | C11: [Paragraph] The Health Impact [H2] This is what degraded oil does to the people eating it. [Paragraph] When cooking oil reaches high temperatures or is reused without testing, its chemical structure breaks down through oxidation and thermal stress. The result is a toxic cocktail that transfers directly into food — and into the bodies of everyone who eats it. [H3] Cancer Risk [Paragraph] Degraded oils contain mutagenic compounds and carcinogens. Chronic consumption — and even inhalation of frying fumes — is linked to higher rates of lung, colorectal, and breast cancers in peer-reviewed epidemiological studies. [H3] Cardiovascular Disease [Paragraph] Degraded oils alter your lipid profile — raising LDL (“bad”) cholesterol while lowering HDL (“good”) cholesterol. They promote atherosclerosis: the stiffening and narrowing of arteries that leads to heart attacks and strokes. [H3] Neurological Damage [Paragraph] 4-Hydroxynonenal (4-HNE) — generated in every fryer running degraded PUFA-rich oil — plays a documented role in the progression of neurodegenerative disorders including Alzheimer's and Parkinson's disease. [H3] Trans Fat Formation [Paragraph] Heat alters the structure of unsaturated fats, creating trans fats — the same compounds the FDA moved to eliminate from the food supply. Every hour of frying in degraded oil produces more. [H3] Oxidative Stress [Paragraph] Free radicals and aldehydes from degraded oil damage cells and DNA. This chronic internal stress is linked to premature aging, inflammation, and the development of degenerative diseases. [H3] Digestive Distress [Paragraph] In the short term, rancid oil causes stomach irritation, nausea, and indigestion. The off-flavors — rancid, sour, fishy — are your body telling you the oil should have been changed days ago. [Paragraph] Sources: Harvard T.H. Chan School of Public Health; Grootveld et al. (2021), Frontiers in Nutrition; Choe & Min (2007), Journal of Food Science. | G11: Awaiting review
B12: Most American kitchens have no standard for frying oil. | C12: [Paragraph] The Gap [H2] Most American kitchens have no standard for frying oil. [Paragraph] The FDA hasn't signaled interest. No state has enacted TPM legislation. No bill has been introduced. Nobody is coming to regulate this. [Paragraph] NCOMA changes that. [Pull quote] “The National Cooking Oil Management Association exists to establish what no federal regulation currently requires: a rigorous, knowledge-based standard for how cooking oil is selected, managed, tested, and replaced in American commercial kitchens.” [Paragraph] NCOMA Mission Statement | G12: Awaiting review
B13: The WIYO! seal. Three tiers. One standard. | C13: [Paragraph] The Solution [H2] The WIYO! seal. Three tiers. One standard. [Paragraph] What Is Your Oil? — the question every diner should ask and every kitchen should be able to answer. The WIYO! seal means this kitchen tests, filters, logs, and manages its oil to a published standard. [H3] Managed Oil [Paragraph] Daily filtration. TPM testing daily minimum. Oil discarded at 25% TPM. Fryers covered when idle. Salt at the pass only. Oil Log maintained every service. [H3] Trained Kitchen [Paragraph] Everything in Bronze. At least one NCOMA Certified Oil Technician (COT) on staff. Can name the three degradation pathways. Thermostat verified ±5°C weekly. Dedicated fish fryer. [H3] Full Transparency [Paragraph] Everything in Silver. Oil type disclosed to diners. 30+ days of Oil Log history. 0.5-micron filtration. Consumer-facing WIYO! seal displayed. Annual inspection, 85%+ pass rate. | G13: Awaiting review
B14: Section 7 | C14: [Paragraph] 0 M+ [Paragraph] Foodservice outlets with no oil quality standard [Paragraph] National Restaurant Association, 2025 [Paragraph] 0 % [Paragraph] Of operators who have never tested TPM [Paragraph] NCOMA 2026 State of the Fryer [Paragraph] TPM — the NCOMA discard threshold [Paragraph] Aligned with Codex Alimentarius and EU law [Paragraph] 40–80% [Paragraph] Oil life extension from proper management [Paragraph] Moreira et al., Deep-Fat Frying | G14: Awaiting review
B15: This isn't opinion. It's peer-reviewed chemistry. | C15: [Paragraph] The Science [H2] This isn't opinion. It's peer-reviewed chemistry. [H3] What your customers are actually eating [Paragraph] Aldehydes from degraded oil don't stay in the fryer. They absorb into the food during cooking. Grootveld's team used NMR spectroscopy to measure it: PUFA-rich oils at 180°C generated aldehyde concentrations orders of magnitude above safety thresholds. Those compounds cause the off-flavors — rancid, sour, fishy — that tell you the oil is done. But most kitchens have already served dozens of batches by that point. [Paragraph] Grootveld et al. (2021), Frontiers in Nutrition; (2015), BBC/De Montfort University [H3] What operators are wasting — or worse [Paragraph] The median oil change is every 3 days, regardless of the oil, the menu, the volume, or whether anyone filtered. That schedule either dumps oil with usable cycles left — costing thousands per year — or keeps serving food in oil past the threshold. One fryer, two ways to lose. Managed operators extend oil life 20–40% and know exactly when to change. [Paragraph] NCOMA 2026 State of the Fryer; Moreira et al., Deep-Fat Frying: Fundamentals [H3] Why the oil type matters more than the price [Paragraph] Linoleic acid — the dominant fatty acid in soybean, corn, and conventional sunflower oil — oxidizes 10–40× faster than oleic acid. Same fryer, same temperature, different chemistry. Conventional soybean oil (58% PUFA) lasts 72 fry cycles. High oleic sunflower (9% PUFA) lasts 210. The plant doesn't matter. The fatty acid profile does. [Paragraph] Choe & Min (2007), Journal of Food Science; Holman & Elmer (1947), JAOCS | G15: Awaiting review
B16: Section 9 | C16: [Pull quote] The oil is an ingredient. Manage it like one. | G16: Awaiting review
B17: The 2026 State of the Fryer | C17: [H2] The 2026 State of the Fryer [Paragraph] 412 operators. 38 states. The first comprehensive survey of how American restaurants actually manage their frying oil. The findings are worse than expected. [List item] 78% have never measured TPM [List item] 25% have no filtration equipment at all [List item] 96% unaware of the 25% TPM international standard [List item] 84% cannot name a single oil degradation pathway [Link/CTA] Read the Full Report | G17: Awaiting review
... B20: Footer | C20: [Paragraph] NCOMA [Paragraph] The National Cooking Oil Management Association. The standard American kitchens have been missing. [Paragraph] Certification [List item] The WIYO! Seal [List item] For Operators [List item] For Consumers [List item] Find Certified [Paragraph] Resources [List item] Oil Atlas [List item] Cost Calculator [List item] Field Notes [List item] Reports [Paragraph] Organization [List item] About NCOMA [List item] Contact & Press [Paragraph] Stay informed [Paragraph] Oil science, certification updates, and industry research. [Paragraph] Follow updates at info@whatisinyouroil.com [Paragraph] © 2026 National Cooking Oil Management Association. All rights reserved. | G20: Awaiting review

Sheet The WIYO! Seal
A1: The WIYO! Seal
A2: /seal | https://www.whatisinyouroil.com/seal | 2026-05-26 13:25 | 11 sections
A3: Open live page
A5: Section preview | B5: Section | C5: Current copy | D5: Suggested edit | E5: Edit type | F5: Proposed by | G5: Approval | H5: Approved by | I5: Notes
B6: SEO - Title & meta | C6: [Page <title>] The WIYO! Seal | NCOMA [Meta description] The first industry-built certification for cooking oil management in American commercial kitchens. Know your oil. | G6: Awaiting review
B7: Navigation | C7: [Link/CTA] NCOMA [Link/CTA] The Seal [Link/CTA] For Operators [Link/CTA] For Consumers [Link/CTA] Oil Atlas [Link/CTA] Field Notes [Link/CTA] Reports [Link/CTA] About [Link/CTA] Get Certified | G7: Awaiting review
B8: What the WIYO! seal means — and why it exists. | C8: [Paragraph] The Seal [H1] What the WIYO! seal means — and why it exists. [Paragraph] Over one million US foodservice outlets. [ 1 ] Not one required by federal law to test its frying oil. The WIYO! seal fills that gap. | G8: Awaiting review
B9: Certified Oil Manager | C9: [Paragraph] Certified Oil Manager [Paragraph] This designation certifies mastery of the science, management, and testing practices that define professional cooking oil stewardship. | G9: Awaiting review
B10: Three certification tiers | C10: [H2] Three certification tiers [Paragraph] Every tier earns the WIYO! seal. The tier tells diners how deep the commitment goes. Click a card to see the full details. [H3] Managed Oil [Paragraph] The operational baseline [Paragraph] Click to expand [H3] Trained Kitchen [Paragraph] Certified knowledge + equipment [H3] Full Transparency [Paragraph] Consumer-facing excellence [H3] Compare tiers [Paragraph] Every tier earns the WIYO! seal. Higher tiers go deeper. | G10: Awaiting review
B11: How the audit works | C11: [H2] How the audit works [Paragraph] NCOMA inspections evaluate six sections. Each item is pass/fail. Overall pass requires 85% with no zero scores in Section C (oil quality at time of inspection). [Paragraph] Knowledge Assessment [Paragraph] Staff interviewed on degradation pathways, TPM, discard threshold, meter operation, fish isolation, salt protocols, filtration procedure. [Paragraph] Equipment Inspection [Paragraph] Thermostat accuracy, vessel material, utensil standards, filtration equipment condition, TPM meter calibration, fryer covers. [Paragraph] Oil Quality at Inspection [Paragraph] Live TPM reading, color assessment, foam check, smoke check, viscosity drip test. This section cannot have zero scores. [Paragraph] Operational Protocols [Paragraph] Salt station placement, oil storage conditions, FIFO rotation, post-boil-out protocol, fish/allergen isolation. [Paragraph] Record-Keeping [Paragraph] Oil Log currency, TPM readings logged, filtration events documented, discard decisions recorded, 30+ days history (Gold). [Paragraph] Filtration Compliance [Paragraph] Daily filtration documented, filter media change records, no visible carbon buildup on heating elements, equipment clean and functional. | G11: Awaiting review
B12: Pricing | C12: [H2] Pricing [Paragraph] Certification pricing varies by operation size, number of fryers, and tier level. Individual COT exams, single-kitchen COMK inspections, and multi-unit COMP programs are each priced separately. [Link/CTA] Request a Quote | G12: Awaiting review
B13: Frequently asked questions | C13: [H2] Frequently asked questions [H3] What does the WIYO! seal mean? [Paragraph] It means the kitchen has been inspected and certified to manage its frying oil to the NCOMA standard — daily filtration, TPM testing, 25% discard threshold, trained staff, and documented record-keeping. It is not a one-time badge; it requires ongoing compliance and annual renewal. [H3] What is TPM and why 25%? [Paragraph] Total Polar Materials is the percentage of degradation products in frying oil. It captures all three degradation pathways — hydrolysis, oxidation, and polymerization — in a single number. Germany mandates discard at 27%, Belgium/Spain/France at 25%. The US has no federal threshold. NCOMA adopts 25%, aligned with the more protective international standards. [H3] How often is oil tested? [Paragraph] Minimum daily in all operations with active fryers. Every service period is recommended during heavy frying (4+ continuous hours). All readings are recorded in the NCOMA Oil Log. [H3] What does the audit check? [Paragraph] Six sections: staff knowledge (can they explain degradation pathways, TPM, and meter operation?), equipment inspection (thermostat accuracy, filtration gear, covers), oil quality at time of inspection (TPM reading, color, foam, smoke, viscosity), operational protocols (salt station placement, oil storage, fish isolation), record-keeping (Oil Log current with 30+ days of history), and filtration compliance. [H3] What's the difference between Bronze, Silver, and Gold? [Paragraph] All three tiers earn the WIYO! seal. Bronze covers the operational baseline — daily filtration, TPM testing, proper discard protocols. Silver adds certified staff (COT designation) and equipment verification. Gold adds full consumer transparency — oil type disclosed to diners, cost-per-cycle tracking, and advanced filtration. [H3] Do I need special equipment? [Paragraph] You need a TPM meter (testo 270 or equivalent, ~$300–600), filtration equipment (portable pump system at minimum), and stainless steel utensils for oil contact. Gold tier recommends 0.5-micron filtration. No proprietary equipment is required. [H3] How long does certification take? [Paragraph] Individual COT certification requires passing the knowledge exam. Kitchen COMK certification requires implementing all operational protocols and passing an on-site inspection. Most kitchens that already filter daily can reach Bronze within 2–4 weeks of protocol implementation. [H3] What does it cost? [Paragraph] Pricing is tailored to operation size and tier. Contact us at certification@whatisinyouroil.com for a quote. [H3] As a diner, how do I verify a restaurant is certified? [Paragraph] Look for the WIYO! seal on the window, menu, or table tent. You can also search the certified operator directory at whatisinyouroil.com/find. Each certified kitchen has a verification code linked to its current certification status. [H3] What happens if a certified kitchen fails re-inspection? [Paragraph] The kitchen enters a 30-day corrective window. If the issues are resolved and a re-inspection passes, certification continues. If not, the WIYO! seal must be removed until the kitchen re-qualifies. | G13: Awaiting review
B14: Verify a certification | C14: [H2] Verify a certification [Paragraph] Enter a restaurant's WIYO! verification code to check current status. [Button] Verify [Paragraph] Verification database launching with certified operators. | G14: Awaiting review
B15: References | C15: [H3] References [List item] National Restaurant Association, 2025 Industry Statistics. The US restaurant industry comprises more than 1 million restaurant and foodservice outlets. | G15: Awaiting review
B16: Footer | C16: [Paragraph] NCOMA [Paragraph] The National Cooking Oil Management Association. The standard American kitchens have been missing. [Paragraph] Certification [List item] The WIYO! Seal [List item] For Operators [List item] For Consumers [List item] Find Certified [Paragraph] Resources [List item] Oil Atlas [List item] Cost Calculator [List item] Field Notes [List item] Reports [Paragraph] Organization [List item] About NCOMA [List item] Contact & Press [Paragraph] Stay informed [Paragraph] Oil science, certification updates, and industry research. [Paragraph] Follow updates at info@whatisinyouroil.com [Paragraph] © 2026 National Cooking Oil Management Association. All rights reserved. | G16: Awaiting review

Sheet For Operators
A1: For Operators
A2: /operators | https://www.whatisinyouroil.com/operators | 2026-05-26 13:25 | 10 sections
A3: Open live page
A5: Section preview | B5: Section | C5: Current copy | D5: Suggested edit | E5: Edit type | F5: Proposed by | G5: Approval | H5: Approved by | I5: Notes
B6: SEO - Title & meta | C6: [Page <title>] For Operators | NCOMA [Meta description] The first industry-built certification for cooking oil management in American commercial kitchens. Know your oil. | G6: Awaiting review
B7: Navigation | C7: [Link/CTA] NCOMA [Link/CTA] The Seal [Link/CTA] For Operators [Link/CTA] For Consumers [Link/CTA] Oil Atlas [Link/CTA] Field Notes [Link/CTA] Reports [Link/CTA] About [Link/CTA] Get Certified | G7: Awaiting review
B8: Stop guessing. Start managing. | C8: [Paragraph] For Operators [H1] Stop guessing. Start managing. [Paragraph] Most restaurants change oil on a fixed schedule — wasting oil with cycles left, or serving food in oil past the threshold. NCOMA-certified operators know the difference. | G8: Awaiting review
B9: Section 2 | C9: [Paragraph] Great frying starts before the food hits the oil. | G9: Awaiting review
B10: The economics of managed oil | C10: [H2] The economics of managed oil [H3] Oil life extension [Paragraph] NCOMA-certified operators extend oil life by 20–40% without compromising food quality. [ 1 ] Daily filtration alone extends oil life by 40–80%. [ 2 ] On a typical oil cost of $1,000–$1,500 per ton and consumption of 50–200+ gallons per week in an active operation, the savings are measured in thousands per month. [H3] Cost per cycle, not cost per gallon [Paragraph] A cheap oil that lasts 70 cycles costs more per productive fry cycle than a premium oil lasting 350 cycles. Example: HO Palm Oil at $1,050/ton delivers 355 cycles — $0.068 per cycle. Conventional sunflower at $1,262/ton delivers 107 cycles — $0.264 per cycle. The “cheaper” oil costs 3.9× more per cycle. [ 3 ] [H3] Food quality improvement [Paragraph] Degraded oil increases fat absorption by 20–40%, producing greasier food with off-flavors from hexanal and short-chain aldehydes. [ 4 ] Managed oil means crispier texture, cleaner flavor, and less oil absorbed per portion — better food and lower oil consumption per cover. [H3] Filtration ROI [Paragraph] Advanced filtration systems like the Zeco (0.5-micron closed-loop) reduce oil consumption by 30–50% across diverse operation types. At typical volumes, monthly savings exceed twice the cost of filtration services — net-positive from the first month. [ 5 ] | G10: Awaiting review
B11: Four steps to certification | C11: [H2] Four steps to certification [H3] Apply [Paragraph] Submit your kitchen profile — fryer count, oil type, menu category, current management practices. No commitment, no fee at this stage. [H3] Audit [Paragraph] An NCOMA inspector evaluates six sections: staff knowledge, equipment, oil quality (live TPM reading), operational protocols, record-keeping, and filtration compliance. 85% pass rate required, no zeros in oil quality. [H3] Certify [Paragraph] Pass the inspection and receive your WIYO! seal — Bronze, Silver, or Gold based on your level of compliance. Display it. Tell your guests. [H3] Renew [Paragraph] Kitchen certification requires annual re-inspection. Individual COT certification is valid for 2 years. Keep your Oil Log current — it's your proof of ongoing compliance. [Link/CTA] Start Your Application | G11: Awaiting review
B12: What auditors check | C12: [H2] What auditors check [Paragraph] A preview of the NCOMA kitchen inspection checklist. No surprises — every item is published in the Certified Cooking Oil Management Guide. [Paragraph] Staff can name the three oil degradation pathways [Paragraph] Staff can explain TPM without reference material [Paragraph] Staff know the 25% TPM discard threshold [Paragraph] Staff can demonstrate correct TPM meter operation [Paragraph] Thermostat verified accurate within ±5°C [Paragraph] No copper or brass utensils in oil contact [Paragraph] Filtration equipment present and working [Paragraph] TPM meter calibrated per manufacturer schedule [Paragraph] Oil color within acceptable range for oil type [Paragraph] No persistent foam at operating temperature [Paragraph] Salt station at the pass, not near the fryer [Paragraph] Oil storage sealed, dark, away from heat [Paragraph] NCOMA Oil Log current (within last service) [Paragraph] Fish/allergen fryer dedicated or documented protocol [Paragraph] Daily filtration documented in log [Paragraph] No visible carbon buildup on heating elements | G12: Awaiting review
B13: Pricing | C13: [H2] Pricing [Paragraph] Certification pricing varies by operation size and tier. Each tier builds on the one below it: [Paragraph] On-site inspection, WIYO! Bronze seal, Oil Log templates, annual renewal. [Paragraph] Everything in Bronze, plus COT exam for one staff member, equipment verification. [Paragraph] Everything in Silver, plus consumer-facing WIYO! seal kit, cost-per-cycle analytics, priority directory listing. [Link/CTA] Request a Quote | G13: Awaiting review
B14: References | C14: [H3] References [List item] NCOMA Certified Cooking Oil Management Guide, 2025. Section 5: Operator ROI. [List item] Moreira, R. G., et al. Deep-Fat Frying: Fundamentals and Applications. Aspen Publishers. [List item] NCOMA Guide, Part 8, Section 8.2. Cost per fry cycle calculation using Fedepalma/UCaldas (2025) frying life data. [List item] Saguy, I. S., & Dana, D. (2003). Minimizing oil uptake during deep-fat frying. Journal of Food Engineering, 56(2–3), 143–152. [List item] Zeco Oil Filtration Systems. Manufacturer data and customer testimonials. | G14: Awaiting review
B15: Footer | C15: [Paragraph] NCOMA [Paragraph] The National Cooking Oil Management Association. The standard American kitchens have been missing. [Paragraph] Certification [List item] The WIYO! Seal [List item] For Operators [List item] For Consumers [List item] Find Certified [Paragraph] Resources [List item] Oil Atlas [List item] Cost Calculator [List item] Field Notes [List item] Reports [Paragraph] Organization [List item] About NCOMA [List item] Contact & Press [Paragraph] Stay informed [Paragraph] Oil science, certification updates, and industry research. [Paragraph] Follow updates at info@whatisinyouroil.com [Paragraph] © 2026 National Cooking Oil Management Association. All rights reserved. | G15: Awaiting review

Sheet For Consumers
A1: For Consumers
A2: /consumers | https://www.whatisinyouroil.com/consumers | 2026-05-26 13:25 | 10 sections
A3: Open live page
A5: Section preview | B5: Section | C5: Current copy | D5: Suggested edit | E5: Edit type | F5: Proposed by | G5: Approval | H5: Approved by | I5: Notes
B6: SEO - Title & meta | C6: [Page <title>] For Consumers | NCOMA [Meta description] The first industry-built certification for cooking oil management in American commercial kitchens. Know your oil. | G6: Awaiting review
B7: Navigation | C7: [Link/CTA] NCOMA [Link/CTA] The Seal [Link/CTA] For Operators [Link/CTA] For Consumers [Link/CTA] Oil Atlas [Link/CTA] Field Notes [Link/CTA] Reports [Link/CTA] About [Link/CTA] Get Certified | G7: Awaiting review
B8: What you fry in is what you serve. | C8: [Paragraph] For Consumers [H1] What you fry in is what you serve. [Paragraph] You check sourcing. You read labels. You ask if the chicken is antibiotic-free. But nobody asks about the oil it's fried in — and right now, there's no way to know if it was tested today or last tested never. | G8: Awaiting review
B9: Section 2 | C9: [Paragraph] Your food is only as good as the oil it's cooked in. | G9: Awaiting review
B10: Why the oil matters | C10: [H2] Why the oil matters [Paragraph] Frying oil degrades every time food enters the fryer. Water from the food triggers hydrolysis. Oxygen in the air drives oxidation. Over time, these reactions produce compounds called total polar materials (TPM) — a mix of free fatty acids, aldehydes, and polymers that affect taste, texture, and health outcomes. [Paragraph] At least five European countries mandate that restaurants discard frying oil when TPM exceeds 25–27%. [ 1 ] The United States has no such requirement. Most American restaurants have never measured their frying oil TPM. The decision to change oil is typically based on a fixed schedule or visual appearance — neither of which reliably predicts actual oil quality. [Paragraph] Grootveld et al. (2017) demonstrated that PUFA-rich oils at frying temperatures generate volatile aldehydes — including 4-hydroxynonenal and malondialdehyde — at levels that may exceed WHO tolerable daily intake thresholds. The choice of frying oil and its state of degradation directly affects what diners ingest. [Paragraph] Grootveld et al. (2017), Lipids in Health and Disease, 16(1), 214. [Paragraph] Degraded oil also changes the food itself. Saguy & Dana (2003) showed that food fried in degraded oil absorbs 20–40% more fat than food fried in properly managed oil. [ 2 ] The texture gets softer and greasier. Off-flavors from oxidation products — rancid, sour, sometimes fishy — transfer to the food. Color darkens prematurely. [Paragraph] None of this is visible to the diner. You cannot tell by looking at a plate of fries whether the oil was fresh or overdue for replacement. That information asymmetry is the problem the WIYO! seal solves. | G10: Awaiting review
B11: What the WIYO! seal tells you | C11: [H2] What the WIYO! seal tells you [Paragraph] The kitchen filters its oil daily — at minimum [Paragraph] Frying oil is tested with a TPM meter, not guessed at [Paragraph] Oil is discarded at 25% TPM — the standard used in Belgium, Spain, France, and the Netherlands [Paragraph] At least one staff member is trained in oil chemistry and degradation science (Silver+) [Paragraph] The oil type is disclosed to diners (Gold) [Paragraph] Records are kept and available for inspection | G11: Awaiting review
B12: Ask your restaurant | C12: [H2] Ask your restaurant [Paragraph] You don't need a chemistry degree. Three questions change the conversation: [Paragraph] “ What oil do you fry in? ” [Paragraph] The type of oil matters. Fruit oils like palm and high oleic varieties (sunflower, canola) produce far fewer degradation byproducts than conventional PUFA-rich seed oils (corn, soybean, grapeseed) at the same temperature. [Paragraph] “ How often do you test it? ” [Paragraph] If the answer is "we don't" or "we change it every X days," there's no data behind the decision. NCOMA-certified kitchens test TPM at minimum daily. [Paragraph] “ Are you NCOMA certified? ” [Paragraph] The WIYO! seal means the kitchen has been independently inspected and meets a published standard. No seal, no standard. | G12: Awaiting review
B13: Find certified restaurants | C13: [H2] Find certified restaurants [Paragraph] Search the NCOMA directory to find restaurants near you that manage their oil to a real standard. [Link/CTA] Search the Directory | G13: Awaiting review
B14: References | C14: [H3] References [List item] Germany 27% TPM (mandatory), Belgium/Netherlands/Spain/France 25% TPM (mandatory). Source: NCOMA Certified Cooking Oil Management Guide, Table 7.1. [List item] Saguy, I. S., & Dana, D. (2003). Minimizing oil uptake during deep-fat frying. Journal of Food Engineering, 56(2–3), 143–152. | G14: Awaiting review
B15: Footer | C15: [Paragraph] NCOMA [Paragraph] The National Cooking Oil Management Association. The standard American kitchens have been missing. [Paragraph] Certification [List item] The WIYO! Seal [List item] For Operators [List item] For Consumers [List item] Find Certified [Paragraph] Resources [List item] Oil Atlas [List item] Cost Calculator [List item] Field Notes [List item] Reports [Paragraph] Organization [List item] About NCOMA [List item] Contact & Press [Paragraph] Stay informed [Paragraph] Oil science, certification updates, and industry research. [Paragraph] Follow updates at info@whatisinyouroil.com [Paragraph] © 2026 National Cooking Oil Management Association. All rights reserved. | G15: Awaiting review

Sheet About NCOMA
A1: About NCOMA
A2: /about | https://www.whatisinyouroil.com/about | 2026-05-26 13:25 | 8 sections
A3: Open live page
A5: Section preview | B5: Section | C5: Current copy | D5: Suggested edit | E5: Edit type | F5: Proposed by | G5: Approval | H5: Approved by | I5: Notes
B6: SEO - Title & meta | C6: [Page <title>] About NCOMA | NCOMA [Meta description] The first industry-built certification for cooking oil management in American commercial kitchens. Know your oil. | G6: Awaiting review
B7: Navigation | C7: [Link/CTA] NCOMA [Link/CTA] The Seal [Link/CTA] For Operators [Link/CTA] For Consumers [Link/CTA] Oil Atlas [Link/CTA] Field Notes [Link/CTA] Reports [Link/CTA] About [Link/CTA] Get Certified | G7: Awaiting review
B8: We built the standard the industry never had. | C8: [Paragraph] About [H1] We built the standard the industry never had. | G8: Awaiting review
B9: Our Story | C9: [H2] Our Story [Paragraph] The National Cooking Oil Management Association exists because of an absence. There is no federal regulation in the United States that tells a restaurant when to change its frying oil. No TPM threshold. No required testing frequency. No certification for the people managing what is, by volume and by impact, one of the most consequential ingredients in commercial cooking. [Paragraph] Germany mandates discard at 27% TPM. Belgium, the Netherlands, Spain, and France set the line at 25%. The United States has nothing — and in the gap, a million-plus foodservice outlets operate on instinct, arbitrary schedules, and visual guesswork. [Paragraph] NCOMA was built by the people who have been inside America's fryers for decades — not by regulators, not by academics, but by the industry itself. Operators who opened 240+ restaurants, engineers who invented patented filtration systems, and strategists who saw the same problem from different angles and decided it was time for a standard. [Paragraph] The association's first act was to produce the Certified Cooking Oil Management Guide — a 10-part reference text covering oil chemistry, degradation science, fryer types, filtration systems, ingredient variables, testing methods, and a complete certification framework. It draws on published research from Choe & Min, Grootveld, Saguy & Dana, the PREDIMED trial, USDA FoodData Central, and original frying performance data from Fedepalma/Universidad de Caldas. [Paragraph] From that foundation, NCOMA built three things: a knowledge-based exam for individual certification (the Certified Oil Manager designation), an operational inspection standard for kitchens, and the WIYO! consumer seal — so diners can see, at a glance, whether their restaurant manages its oil to a real standard. [Paragraph] Our mission is simple: raise the standard of oil management in every commercial kitchen in this country. One kitchen at a time. | G9: Awaiting review
B10: Mission | C10: [H2] Mission [Pull quote] The National Cooking Oil Management Association exists to establish what no federal regulation currently requires: a rigorous, knowledge-based standard for how cooking oil is selected, managed, tested, and replaced in American commercial kitchens. [Paragraph] We believe that better-managed oil means better food and safer kitchens. The NCOMA Certified Oil Manager designation is how we get there — one kitchen at a time. | G10: Awaiting review
B11: Leadership | C11: [H2] Leadership [Paragraph] Matt McMahon [Paragraph] President & Co-Founder [Paragraph] NCOMA [Paragraph] Former President of McMahon Restaurant Group, where he opened 24 Outback Steakhouses across Arizona and New Mexico, reaching $72M+ in annual sales. Supervised 94 restaurants in 16 states and opened over 240 locations in 8 years. Developed Bulk Oil Management Solutions that saved over 100,000 lbs of oil waste. Now leads NCOMA's mission to bring science-based oil management to every commercial kitchen in America. [Link/CTA] LinkedIn → [Paragraph] Conrad Canter [Paragraph] Co-Founder & Technical Director [Paragraph] SK Oil Sales / Zeco [Paragraph] Inventor of the Zeco Oil Filtration Machine — a patented closed-loop system that microfilters cooking oil down to 0.5 microns, removing 99% of free radicals and contaminants. Over 50 years of business experience spanning commercial printing, filtration engineering, and foodservice. As Managing Partner of SK Oil Sales, delivers filtration and bulk oil systems to hundreds of restaurants and casinos across Arizona, California, Nevada, and New Mexico. [Paragraph] Pablo Herrera [Paragraph] Founder, The Oil Insurgency [Paragraph] Built the Oil Atlas, designed the certification framework, and launched The Oil Insurgency — the campaign to force transparency into every commercial fryer in America. Previously del Llano Farms. Won't stop asking the questions the oil industry would rather you didn't. | G11: Awaiting review
B12: Contact | C12: [H2] Contact [Paragraph] General inquiries: info@whatisinyouroil.com [Paragraph] Certification: certification@whatisinyouroil.com [Paragraph] Media & press: press@whatisinyouroil.com | G12: Awaiting review
B13: Footer | C13: [Paragraph] NCOMA [Paragraph] The National Cooking Oil Management Association. The standard American kitchens have been missing. [Paragraph] Certification [List item] The WIYO! Seal [List item] For Operators [List item] For Consumers [List item] Find Certified [Paragraph] Resources [List item] Oil Atlas [List item] Cost Calculator [List item] Field Notes [List item] Reports [Paragraph] Organization [List item] About NCOMA [List item] Contact & Press [Paragraph] Stay informed [Paragraph] Oil science, certification updates, and industry research. [Paragraph] Follow updates at info@whatisinyouroil.com [Paragraph] © 2026 National Cooking Oil Management Association. All rights reserved. | G13: Awaiting review

Sheet Contact
A1: Contact
A2: /contact | https://www.whatisinyouroil.com/contact | 2026-05-26 13:25 | 6 sections
A3: Open live page
A5: Section preview | B5: Section | C5: Current copy | D5: Suggested edit | E5: Edit type | F5: Proposed by | G5: Approval | H5: Approved by | I5: Notes
B6: SEO - Title & meta | C6: [Page <title>] NCOMA — National Cooking Oil Management Association [Meta description] The first industry-built certification for cooking oil management in American commercial kitchens. Know your oil. | G6: Awaiting review
B7: Navigation | C7: [Link/CTA] NCOMA [Link/CTA] The Seal [Link/CTA] For Operators [Link/CTA] For Consumers [Link/CTA] Oil Atlas [Link/CTA] Field Notes [Link/CTA] Reports [Link/CTA] About [Link/CTA] Get Certified | G7: Awaiting review
B8: Get in touch | C8: [Paragraph] Contact & Press [H1] Get in touch | G8: Awaiting review
B9: Send us a message | C9: [H2] Send us a message [Label] Name [Label] Email [Label] Subject [Label] Message [Button] Send Message [H3] General Inquiries [Paragraph] info@whatisinyouroil.com [H3] Media & Press [Paragraph] press@whatisinyouroil.com [H3] Speaking Requests [Paragraph] speaking@whatisinyouroil.com [H3] Mailing Address [Paragraph] Scottsdale, AZ | G9: Awaiting review
B10: Press | C10: [H2] Press [H3] About NCOMA — Boilerplate [Paragraph] The National Cooking Oil Management Association (NCOMA) is the first industry-built certification body for cooking oil management in American commercial kitchens. Founded by foodservice industry professionals, NCOMA establishes what no federal regulation currently requires: a science-based standard for how cooking oil is selected, managed, tested, and replaced. The association's WIYO! (“What Is Your Oil?”) consumer seal certifies that a restaurant manages its frying oil to a published standard aligned with international best practice. NCOMA is headquartered in Scottsdale, Arizona. [H3] Founders [Paragraph] Matt McMahon [Paragraph] President & Co-Founder [Paragraph] Former President of McMahon Restaurant Group, where he opened 24 Outback Steakhouses across Arizona and New Mexico. Now leads NCOMA’s mission to bring science-based oil management to every commercial kitchen in America. [Paragraph] Pablo Herrera [Paragraph] Founder, The Oil Insurgency [Paragraph] Built the Oil Atlas, designed the certification framework, and launched The Oil Insurgency — the campaign to force transparency into every commercial fryer in America. | G10: Awaiting review
B11: Footer | C11: [Paragraph] NCOMA [Paragraph] The National Cooking Oil Management Association. The standard American kitchens have been missing. [Paragraph] Certification [List item] The WIYO! Seal [List item] For Operators [List item] For Consumers [List item] Find Certified [Paragraph] Resources [List item] Oil Atlas [List item] Cost Calculator [List item] Field Notes [List item] Reports [Paragraph] Organization [List item] About NCOMA [List item] Contact & Press [Paragraph] Stay informed [Paragraph] Oil science, certification updates, and industry research. [Paragraph] Follow updates at info@whatisinyouroil.com [Paragraph] © 2026 National Cooking Oil Management Association. All rights reserved. | G11: Awaiting review

Sheet Find Certified
A1: Find Certified
A2: /find | https://www.whatisinyouroil.com/find | 2026-05-26 13:26 | 5 sections
A3: Open live page
A5: Section preview | B5: Section | C5: Current copy | D5: Suggested edit | E5: Edit type | F5: Proposed by | G5: Approval | H5: Approved by | I5: Notes
B6: SEO - Title & meta | C6: [Page <title>] NCOMA — National Cooking Oil Management Association [Meta description] The first industry-built certification for cooking oil management in American commercial kitchens. Know your oil. | G6: Awaiting review
B7: Navigation | C7: [Link/CTA] NCOMA [Link/CTA] The Seal [Link/CTA] For Operators [Link/CTA] For Consumers [Link/CTA] Oil Atlas [Link/CTA] Field Notes [Link/CTA] Reports [Link/CTA] About [Link/CTA] Get Certified | G7: Awaiting review
B8: Certified restaurant directory | C8: [Paragraph] Find Certified [H1] Certified restaurant directory [Paragraph] Every restaurant listed here has been inspected by NCOMA and meets the published standard for cooking oil management. Search by name, location, or oil type. | G8: Awaiting review
B9: Search results | C9: [Button] All Tiers [Button] Bronze [Button] Silver [Button] Gold [H2] Search results [H3] The Golden Fryer [Paragraph] 142 Main St, Austin, TX 78701 [Paragraph] Verification: wiyo-2026-00001 [Paragraph] Last inspection: Jan 14, 2026 [H3] Crisp & Co. [Paragraph] 800 Congress Ave, Austin, TX 78701 [Paragraph] Verification: wiyo-2026-00002 [Paragraph] Last inspection: Jan 31, 2026 [H3] Fat Duck Kitchen [Paragraph] 1500 Red River St, Austin, TX 78701 [Paragraph] Verification: wiyo-2026-00003 [Paragraph] Last inspection: Mar 9, 2026 [H3] Nashville Heat [Paragraph] 422 Broadway, Nashville, TN 37203 [Paragraph] Verification: wiyo-2026-00004 [Paragraph] Last inspection: Jan 19, 2026 [H3] Fryer's Delight [Paragraph] 75 9th Ave, New York, NY 10011 [Paragraph] Verification: wiyo-2026-00005 [Paragraph] Last inspection: Feb 14, 2026 [H3] The Oil Standard [Paragraph] 500 Bourbon St, New Orleans, LA 70130 [Paragraph] Verification: wiyo-2026-00006 [Paragraph] Last inspection: Feb 28, 2026 [H3] South Fry Co. [Paragraph] 200 Peachtree St NE, Atlanta, GA 30303 [Paragraph] Verification: wiyo-2026-00007 [Paragraph] Last inspection: Mar 31, 2026 [H3] Pacific Tempura House [Paragraph] 1 Ferry Building, San Francisco, CA 94111 [Paragraph] Verification: wiyo-2026-00008 [Paragraph] Last inspection: Feb 27, 2026 | G9: Awaiting review
B10: Footer | C10: [Paragraph] NCOMA [Paragraph] The National Cooking Oil Management Association. The standard American kitchens have been missing. [Paragraph] Certification [List item] The WIYO! Seal [List item] For Operators [List item] For Consumers [List item] Find Certified [Paragraph] Resources [List item] Oil Atlas [List item] Cost Calculator [List item] Field Notes [List item] Reports [Paragraph] Organization [List item] About NCOMA [List item] Contact & Press [Paragraph] Stay informed [Paragraph] Oil science, certification updates, and industry research. [Paragraph] Follow updates at info@whatisinyouroil.com [Paragraph] © 2026 National Cooking Oil Management Association. All rights reserved. | G10: Awaiting review

Sheet Field Notes Index
A1: Field Notes Index
A2: /field-notes | https://www.whatisinyouroil.com/field-notes | 2026-05-26 13:26 | 5 sections
A3: Open live page
A5: Section preview | B5: Section | C5: Current copy | D5: Suggested edit | E5: Edit type | F5: Proposed by | G5: Approval | H5: Approved by | I5: Notes
B6: SEO - Title & meta | C6: [Page <title>] Field Notes | NCOMA [Meta description] The first industry-built certification for cooking oil management in American commercial kitchens. Know your oil. | G6: Awaiting review
B7: Navigation | C7: [Link/CTA] NCOMA [Link/CTA] The Seal [Link/CTA] For Operators [Link/CTA] For Consumers [Link/CTA] Oil Atlas [Link/CTA] Field Notes [Link/CTA] Reports [Link/CTA] About [Link/CTA] Get Certified | G7: Awaiting review
B8: Science for the kitchen. | C8: [Paragraph] Field Notes [H1] Science for the kitchen. [Paragraph] Oil chemistry, degradation science, filtration, and best practices — written for operators, not academics. | G8: Awaiting review
B9: The Six Enemies of Frying Oil (and How to Beat Each One) | C9: [H2] The Six Enemies of Frying Oil (and How to Beat Each One) [Paragraph] Heat, oxygen, water, salt, metal, and particles. Every factor that degrades your frying oil has a specific mechanism and a specific countermeasure. Here is the operational playbook. [Link/CTA] Operations · May 10, 2026 · 8 min The Six Enemies of Frying Oil (and How to Beat Each One) Heat, oxygen, water, salt, metal, and particles. Every factor that degrades your frying oil has a specific mechanism and a specific countermeasure. Here is the operational playbook. # fryer management # degradation # temperature # salt # filtration # equipment [H2] TPM Testing Explained: What the Number Actually Means [Paragraph] Total Polar Materials is the single most important metric in frying oil management. Here is what it measures, how 20+ countries regulate it, why the US does not, and how to read your meter correctly. [Link/CTA] Oil Science · April 15, 2026 · 8 min TPM Testing Explained: What the Number Actually Means Total Polar Materials is the single most important metric in frying oil management. Here is what it measures, how 20+ countries regulate it, why the US does not, and how to read your meter correctly. # TPM # testing # degradation # food safety [H2] The ROI of Daily Filtration: Real Numbers from Real Kitchens [Paragraph] Daily filtration extends oil life by 40–80%. But which method, at what cost, and what does the payback actually look like? Data from Pitco, Henny Penny, RTI, and Zeco. [Link/CTA] Operations · March 20, 2026 · 7 min The ROI of Daily Filtration: Real Numbers from Real Kitchens Daily filtration extends oil life by 40–80%. But which method, at what cost, and what does the payback actually look like? Data from Pitco, Henny Penny, RTI, and Zeco. # filtration # ROI # cost savings # oil management # equipment [H2] Choosing a Frying Oil: What the Science Says [Paragraph] The choice of frying oil is a chemistry decision masquerading as a purchasing decision. Fatty acid composition — not brand, not price per gallon, not smoke point — determines how long your oil lasts and what it produces when it degrades. [Link/CTA] Oil Science · February 10, 2026 · 9 min Choosing a Frying Oil: What the Science Says The choice of frying oil is a chemistry decision masquerading as a purchasing decision. Fatty acid composition — not brand, not price per gallon, not smoke point — determines how long your oil lasts and what it produces when it degrades. # oil selection # fatty acids # MUFA # PUFA # aldehydes # frying performance [H2] 20+ Countries Regulate Frying Oil. The United States Is Not One of Them. [Paragraph] Germany set the first frying oil standard in 1973. More than 20 countries now mandate TPM testing and discard thresholds. The US has no federal requirement — and no state has filled the gap. [Link/CTA] Policy · January 15, 2026 · 7 min 20+ Countries Regulate Frying Oil. The United States Is Not One of Them. Germany set the first frying oil standard in 1973. More than 20 countries now mandate TPM testing and discard thresholds. The US has no federal requirement — and no state has filled the gap. # regulation # TPM # food safety # international standards # US policy | G9: Awaiting review
B10: Footer | C10: [Paragraph] NCOMA [Paragraph] The National Cooking Oil Management Association. The standard American kitchens have been missing. [Paragraph] Certification [List item] The WIYO! Seal [List item] For Operators [List item] For Consumers [List item] Find Certified [Paragraph] Resources [List item] Oil Atlas [List item] Cost Calculator [List item] Field Notes [List item] Reports [Paragraph] Organization [List item] About NCOMA [List item] Contact & Press [Paragraph] Stay informed [Paragraph] Oil science, certification updates, and industry research. [Paragraph] Follow updates at info@whatisinyouroil.com [Paragraph] © 2026 National Cooking Oil Management Association. All rights reserved. | G10: Awaiting review

Sheet Reports Index
A1: Reports Index
A2: /reports | https://www.whatisinyouroil.com/reports | 2026-05-26 13:26 | 5 sections
A3: Open live page
A5: Section preview | B5: Section | C5: Current copy | D5: Suggested edit | E5: Edit type | F5: Proposed by | G5: Approval | H5: Approved by | I5: Notes
B6: SEO - Title & meta | C6: [Page <title>] Reports | NCOMA [Meta description] The first industry-built certification for cooking oil management in American commercial kitchens. Know your oil. | G6: Awaiting review
B7: Navigation | C7: [Link/CTA] NCOMA [Link/CTA] The Seal [Link/CTA] For Operators [Link/CTA] For Consumers [Link/CTA] Oil Atlas [Link/CTA] Field Notes [Link/CTA] Reports [Link/CTA] About [Link/CTA] Get Certified | G7: Awaiting review
B8: Research and industry data. | C8: [Paragraph] Reports [H1] Research and industry data. [Paragraph] Original research on oil management, cost economics, and frying science. Data that makes the case for managed oil. | G8: Awaiting review
B9: 2026 State of the Fryer | C9: [H2] 2026 State of the Fryer [Paragraph] Oil Management Practices in American Commercial Kitchens [Paragraph] The first industry-wide assessment of how American commercial kitchens manage their frying oil. 412 operators surveyed on testing, oil selection, filtration, and awareness of international standards. The findings are worse than expected. [Link/CTA] Annual Report · May 2026 · 12 min 2026 State of the Fryer Oil Management Practices in American Commercial Kitchens The first industry-wide assessment of how American commercial kitchens manage their frying oil. 412 operators surveyed on testing, oil selection, filtration, and awareness of international standards. The findings are worse than expected. [H2] Frying Oil Performance Rankings: 20 Oils Compared by Science [Paragraph] Fry Cycle, Fatty Acid, and Stability Data from Standardized Trials [Paragraph] Standardized frying trial data for 20 oils, ranked by fry cycles to 25% TPM. Combined with USDA fatty acid composition and published oxidative stability data to create the most comprehensive frying oil performance comparison available. [Link/CTA] Research · April 2026 · 10 min Frying Oil Performance Rankings: 20 Oils Compared by Science Fry Cycle, Fatty Acid, and Stability Data from Standardized Trials Standardized frying trial data for 20 oils, ranked by fry cycles to 25% TPM. Combined with USDA fatty acid composition and published oxidative stability data to create the most comprehensive frying oil performance comparison available. | G9: Awaiting review
B10: Footer | C10: [Paragraph] NCOMA [Paragraph] The National Cooking Oil Management Association. The standard American kitchens have been missing. [Paragraph] Certification [List item] The WIYO! Seal [List item] For Operators [List item] For Consumers [List item] Find Certified [Paragraph] Resources [List item] Oil Atlas [List item] Cost Calculator [List item] Field Notes [List item] Reports [Paragraph] Organization [List item] About NCOMA [List item] Contact & Press [Paragraph] Stay informed [Paragraph] Oil science, certification updates, and industry research. [Paragraph] Follow updates at info@whatisinyouroil.com [Paragraph] © 2026 National Cooking Oil Management Association. All rights reserved. | G10: Awaiting review

Sheet Cost Calculator
A1: Cost Calculator
A2: /tools/cost-calculator | https://www.whatisinyouroil.com/tools/cost-calculator | 2026-05-26 13:26 | 5 sections
A3: Open live page
A5: Section preview | B5: Section | C5: Current copy | D5: Suggested edit | E5: Edit type | F5: Proposed by | G5: Approval | H5: Approved by | I5: Notes
B6: SEO - Title & meta | C6: [Page <title>] NCOMA — National Cooking Oil Management Association [Meta description] The first industry-built certification for cooking oil management in American commercial kitchens. Know your oil. | G6: Awaiting review
B7: Navigation | C7: [Link/CTA] NCOMA [Link/CTA] The Seal [Link/CTA] For Operators [Link/CTA] For Consumers [Link/CTA] Oil Atlas [Link/CTA] Field Notes [Link/CTA] Reports [Link/CTA] About [Link/CTA] Get Certified | G7: Awaiting review
B8: Oil cost calculator | C8: [Paragraph] Tools [H1] Oil cost calculator [Paragraph] Enter your actual numbers — what you pay, how much you use, how often you change. See what NCOMA-standard oil management (daily filtration + TPM testing + condition-based discard) saves you. | G8: Awaiting review
